<?xml version="1.0" encoding="UTF-8"?>
<robot name="roco_arm">
   <link name="base_link">
      <visual>
         <geometry>
            <cylinder length="0.06" radius="0.1" />
         </geometry>
      </visual>
   </link>

   <link name="base_rotator">
      <visual>
         <geometry>
            <cylinder length="0.03" radius="0.1" />
         </geometry>
      </visual>
   </link>

   <link name="first_segment">
      <visual>
         <geometry>
            <box size="0.6 0.05 0.1" />
         </geometry>
         <origin rpy="0 0 0" xyz="-0.3 0 0" />
      </visual>
   </link>

   <link name="second_segment">
      <visual>
         <geometry>
            <box size="0.6 0.05 0.1" />
         </geometry>
         <origin rpy="0 0 0" xyz="-0.3 0 0" />
      </visual>
   </link>
   
   <joint name="base_to_rotator" type="revolute">
      <axis xyz="0 0 1" />
      <limit effort="1000" lower="0" upper="3.14" velocity="0.5" />
      <parent link="base_link" />
      <child link="base_rotator" />
      <origin xyz="0 0 0.03" />
   </joint>

	<joint name="rotator_to_first" type="revolute">
      <axis xyz="0 1 0" />
      <limit effort="1000" lower="0" upper="3.14" velocity="0.5" />
      <parent link="base_rotator" />
      <child link="first_segment" />
      <origin xyz="0 0 0.015" />
   </joint>

   <joint name="first_to_second" type="revolute">
      <axis xyz="0 -1 0" />
      <limit effort="1000" lower="-2.07" upper="2.07" velocity="0.5" />
      <parent link="first_segment" />
      <child link="second_segment" />
      <origin xyz="-0.6 0 0" />
   </joint>
</robot>